Workbook

Sheet 76A Ingelow Road
B1: Swedish Tax Period | C1: 2023 | D1: 2023 | E1: 2023 | F1: 2023 | G1: 2023 | H1: 2023 | I1: 2023 | J1: 2023 | K1: 2023 | L1: 2023 | M1: 2023 | N1: 2023 | O1: 2023 | P1: 2024 | Q1: 2024 | R1: 2024 | S1: 2024 | T1: 2024 | U1: 2024 | V1: 2024 | W1: 2024 | X1: 2024 | Y1: 2024 | Z1: 2024 | AA1: 2024 | AB1: 2024 | AC1: 2024 | AD1: 2024 | AE1: 2024 | AF1: 2024 | AG1: 2025 | AH1: 2025 | AI1: 2025 | AJ1: 2025 | AK1: 2025 | AL1: 2025 | AM1: 2025 | AN1: 2025 | AO1: 2025 | AP1: 2025 | AQ1: 2025 | AR1: 2025 | AS1: 2025 | AT1: 2026 | AU1: 2026 | AV1: 2026 | AW1: 2026 | AX1: 2026 | AY1: 2026
B2: UK Tax Period | C2: 23.24 | D2: 23.24 | E2: 23.24 | F2: 23.24 | G2: 23.24 | H2: 23.24 | I2: 23.24 | J2: 23.24 | K2: 23.24 | L2: 23.24 | M2: 23.24 | N2: 23.24 | O2: 23.24 | P2: 23.24 | Q2: 23.24 | R2: 23.24 | S2: 24.25 | T2: 24.25 | U2: 24.25 | V2: 24.25 | W2: 24.25 | X2: 24.25 | Y2: 24.25 | Z2: 24.25 | AA2: 24.25 | AB2: 24.25 | AC2: 24.25 | AD2: 24.25 | AE2: 24.25 | AF2: 24.25 | AG2: 24.25 | AH2: 24.25 | AI2: 24.25 | AJ2: 25.26 | AK2: 25.26 | AL2: 25.26 | AM2: 25.26 | AN2: 25.26 | AO2: 25.26 | AP2: 25.26 | AQ2: 25.26 | AR2: 25.26 | AS2: 25.26 | AT2: 25.26 | AU2: 25.26 | AV2: 25.26 | AW2: 25.26 | AX2: 26.27 | AY2: 26.27
B3: Knight Frank Statement No. | C3: 29 | D3: 30 | E3: 31 | F3: 32 | G3: 33 | H3: 34 | I3: 35 | J3: 36 | K3: 37 | L3: 38 | M3: 39 | N3: 40 | O3: 41 | P3: 42 | Q3: 43 | R3: 44 | S3: 45 | T3: 46 | U3: 47 | V3: 48 | W3: 49 | X3: 50 | Y3: 51 | Z3: 52 | AA3: 53 | AB3: 54 | AC3: 55 | AD3: 56 | AE3: 57 | AF3: 58 | AG3: 59 | AH3: 60 | AI3: 61 | AJ3: 62 | AK3: 63 | AL3: 64 | AM3: 65 | AN3: 66 | AO3: 67 | AP3: 68 | AQ3: 69 | AR3: 70 | AS3: 71 | AT3: 72 | AU3: 73 | AV3: 74 | AW3: 75 | AX3: 76 | AY3: 77
B4: Period | C4: April | D4: April | E4: May | F4: June | G4: July | H4: August | I4: September | J4: September | K4: October | L4: November | M4: November | N4: December | O4: December | P4: January | Q4: February | R4: March | S4: April | T4: April | U4: May | V4: May | W4: June | X4: June | Y4: July | Z4: August | AA4: August | AB4: September | AC4: October | AD4: November | AE4: November | AF4: December | AG4: January | AH4: February | AI4: March | AJ4: April | AK4: May | AL4: May | AM4: June | AN4: August | AO4: September | AP4: October | AQ4: November | AR4: December | AS4: December | AT4: February | AU4: March | AV4: March | AW4: March | AX4: April | AY4: April
B6: Income | C6: 1125 | D6: 1125 | E6: 2250 | F6: 2250 | G6: 2250 | H6: 2250 | I6: 1125 | J6: 1125 | K6: 2250 | L6: 1125 | M6: 1125 | N6: 1213 | O6: 1213 | P6: 2427 | Q6: 2427 | R6: 2427 | S6: 1327.34 | T6: 1213.31 | U6: 1213.27 | V6: 1213.27 | W6: 1213.25 | X6: 1213.34 | Y6: 2426.57 | Z6: 1213.21 | AA6: 1213.24 | AB6: 2426.53 | AC6: 2426 | AD6: 1213.15 | AE6: 1213.34 | AF6: 2600 | AG6: 2600 | AH6: 2600 | AI6: 2600 | AJ6: 2600 | AK6: 2600 | AL6: 2600 | AM6: 2600 | AN6: 2600 | AO6: 2600 | AP6: 2600 | AQ6: 2600 | AR6: 2650 | AS6: 2650 | AT6: 2650 | AU6: 2650 | AV6: 0 | AW6: 871.25 | AX6: 3000 | AY6: -0.02
B8: Total | C8: =SUM(C6:C7) | D8: =SUM(D6:D7) | E8: =SUM(E6:E7) | F8: =SUM(F6:F7) | G8: =SUM(G6:G7) | H8: =SUM(H6:H7) | I8: =SUM(I6:I7) | J8: =SUM(J6:J7) | ... AY8: =SUM(AY6:AY7)
B10: Management Commission | C10: -54 | D10: -54 | E10: -108 | F10: -108 | G10: -108 | H10: -108 | I10: -54 | J10: -54 | K10: -108 | L10: -54 | M10: -54 | N10: -58 | O10: -58 | P10: -116 | Q10: -116 | R10: -116 | S10: -116.48 | T10: 0 | U10: -116.48 | V10: 0 | W10: -116 | X10: 0 | Y10: -116.47536 | Z10: -116.48 | AA10: 0 | AB10: -116.47344 | AC10: -116.448 | AD10: -116 | AE10: 0 | AF10: -124.8 | AG10: -124.8 | AH10: -124.8 | AI10: -124.8 | AJ10: -124.8 | AK10: -124.8 | AL10: -124.8 | AM10: -124.8 | AN10: -124.8 | AO10: -124.8 | AP10: -124.8 | AQ10: -124.8 | AR10: -127.2 | AS10: -127.2 | AT10: -127.2 | AU10: -127.2 | AV10: 0 | AW10: -50.18 | AX10: -144 | AY10: 0
B11: Letting Commission | N11: -3145 | AF11: -3429.6 | AR11: -3434.4 | AV11: 2192.37 | AW11: -60 | AX11: -4404 | AY11: 27.17
B12: Total Commission | C12: =SUM(C10:C11) | D12: =SUM(D10:D11) | E12: =SUM(E10:E11) | F12: =SUM(F10:F11) | G12: =SUM(G10:G11) | H12: =SUM(H10:H11) | I12: =SUM(I10:I11) | J12: =SUM(J10:J11) | ... AY12: =SUM(AY10:AY11)
B13: Maintenance Expenses | F13: -158 | H13: -298 | L13: -126 | P13: -875 | S13: -114 | Y13: -114 | Z13: -484 | AB13: -90 | AI13: -1322.99 | AK13: -1203 | AN13: -250 | AP13: -156 | AQ13: -312 | AT13: -408 | AU13: -693.6 | AV13: -4920 | AX13: -966 | AY13: -444
B15: Total | C15: =SUM(C8,C12,C13) | D15: =SUM(D8,D12,D13) | E15: =SUM(E8,E12,E13) | F15: =SUM(F8,F12,F13) | G15: =SUM(G8,G12,G13) | H15: =SUM(H8,H12,H13) | I15: =SUM(I8,I12,I13) | J15: =SUM(J8,J12,J13) | ... AY15: =SUM(AY8,AY12,AY13)
B16: Total (Ex. Expenses) | C16: =SUM(C8,C12) | D16: =SUM(D8,D12) | E16: =SUM(E8,E12) | F16: =SUM(F8,F12) | G16: =SUM(G8,G12) | H16: =SUM(H8,H12) | I16: =SUM(I8,I12) | J16: =SUM(J8,J12) | ... AY16: =SUM(AY8,AY12)

Sheet Santander
A1: Period | B1: Apr | C1: May | D1: Jun | E1: Jul | F1: Aug | G1: Sep | H1: Oct | I1: Nov | J1: Dec | K1: Jan | L1: Feb | M1: Mar | N1: Apr | O1: May | P1: Jun | Q1: Jul | R1: Aug | S1: Sep | T1: Oct | U1: Nov | V1: Dec | W1: Jan | X1: Feb | Y1: Mar | Z1: Apr | AA1: May | AB1: Jun | AC1: Jul | AD1: Aug | AE1: Sep | AF1: Oct | AG1: Nov | AH1: Dec | AI1: Jan | AJ1: Feb | AK1: Mar | AL1: Apr | AM1: May
A2: Year | B2: 2023 | C2: 2023 | D2: 2023 | E2: 2023 | F2: 2023 | G2: 2023 | H2: 2023 | I2: 2023 | J2: 2023 | K2: 2024 | L2: 2024 | M2: 2024 | N2: 2024 | O2: 2024 | P2: 2024 | Q2: 2024 | R2: 2024 | S2: 2024 | T2: 2024 | U2: 2024 | V2: 2024 | W2: 2025 | X2: 2025 | Y2: 2025 | Z2: 2025 | AA2: 2025 | AB2: 2025 | AC2: 2025 | AD2: 2025 | AE2: 2025 | AF2: 2025 | AG2: 2025 | AH2: 2025 | AI2: 2026 | AJ2: 2026 | AK2: 2026 | AL2: 2026 | AM2: 2026
A3: UK Tax Year | B3: 23/24 | C3: 23/24 | D3: 23/24 | E3: 23/24 | F3: 23/24 | G3: 23/24 | H3: 23/24 | I3: 23/24 | J3: 23/24 | K3: 23/24 | L3: 23/24 | M3: 23/24 | N3: 24/25 | O3: 24/25 | P3: 24/25 | Q3: 24/25 | R3: 24/25 | S3: 24/25 | T3: 24/25 | U3: 24/25 | V3: 24/25 | W3: 24/25 | X3: 24/25 | Y3: 24/25 | Z3: 25/26 | AA3: 25/26 | AB3: 25/26 | AC3: 25/26 | AD3: 25/26 | AE3: 25/26 | AF3: 25/26 | AG3: 25/26 | AH3: 25/26 | AI3: 25/26 | AJ3: 25/26 | AK3: 25/26 | AL3: 26/27 | AM3: 26/27
A4: Swedish Tax Year | B4: 2023 | C4: 2023 | D4: 2023 | E4: 2023 | F4: 2023 | G4: 2023 | H4: 2023 | I4: 2023 | J4: 2023 | K4: 2024 | L4: 2024 | M4: 2024 | N4: 2024 | O4: 2024 | P4: 2024 | Q4: 2024 | R4: 2024 | S4: 2024 | T4: 2024 | U4: 2024 | V4: 2024 | W4: 2025 | X4: 2025 | Y4: 2025 | Z4: 2025 | AA4: 2025 | AB4: 2025 | AC4: 2025 | AD4: 2025 | AE4: 2025 | AF4: 2025 | AG4: 2025 | AH4: 2025 | AI4: 2026 | AJ4: 2026 | AK4: 2026 | AL4: 2026 | AM4: 2026
A5: Opening (£) | B5: 204100.03 | C5: 202813.07 | D5: 202124.57 | E5: 201435.19 | F5: 200744.97 | G5: 200053.89 | H5: 199361.95 | I5: 198669.15 | J5: 197275.49 | K5: 195880.1 | L5: 194482.99 | M5: 193084.14 | N5: 191683.56 | O5: 190281.24 | P5: 188877.18 | Q5: 187471.37 | R5: 186063.82 | S5: 184654.52 | T5: 183243.47 | U5: 181830.67 | V5: 180416.11 | W5: 178999.86 | X5: 178281.79 | Y5: 179311.84 | Z5: 178764.94 | AA5: 178764.94 | AB5: 178764.94 | AC5: 178764.94 | AD5: 178764.94 | AE5: 178764.94 | AF5: 178764.94 | AG5: 178764.94 | AH5: 178764.94 | AI5: 178764.94 | AJ5: 178764.94 | AK5: 178764.94 | AL5: 178764.94 | AM5: 178764.94
A6: Interest charged (£) | B6: 253.42 | C6: 251.85 | D6: 250.97 | E6: 250.12 | F6: 249.26 | G6: 248.4 | H6: 247.54 | I6: 246.68 | J6: 244.95 | K6: 243.22 | L6: 241.48 | M6: 239.75 | N6: 238.01 | O6: 236.27 | P6: 234.52 | Q6: 232.78 | R6: 231.03 | S6: 229.28 | T6: 227.53 | U6: 225.77 | V6: 224.02 | W6: 222.26 | X6: 221.37 | Y6: 638.98 | Z6: 652.49 | AA6: 652.49 | AB6: 652.49 | AC6: 652.49 | AD6: 652.49 | AE6: 652.49 | AF6: 652.49 | AG6: 652.49 | AH6: 652.49 | AI6: 652.49 | AJ6: 652.49 | AK6: 652.49 | AL6: 652.49 | AM6: 652.49
A7: Capital paid (£) | B7: 1286.96 | C7: 688.5 | D7: 689.38 | E7: 690.22 | F7: 691.08 | G7: 691.94 | H7: 692.8 | I7: 1393.66 | J7: 1395.39 | K7: 1397.11 | L7: 1398.85 | M7: 1400.58 | N7: 1402.32 | O7: 1404.06 | P7: 1405.81 | Q7: 1407.55 | R7: 1409.3 | S7: 1411.05 | T7: 1412.8 | U7: 1414.56 | V7: 1416.31 | W7: 718.07 | X7: 718.95 | Y7: 546.9 | Z7: 0 | AA7: 0 | AB7: 0 | AC7: 0 | AD7: 0 | AE7: 0 | AF7: 0 | AG7: 0 | AH7: 0 | AI7: 0 | AJ7: 0 | AK7: 0 | AL7: 0 | AM7: 0
A8: Product fee (£) | B8: 0 | C8: 0 | D8: 0 | E8: 0 | F8: 0 | G8: 0 | H8: 0 | I8: 0 | J8: 0 | K8: 0 | L8: 0 | M8: 0 | N8: 0 | O8: 0 | P8: 0 | Q8: 0 | R8: 0 | S8: 0 | T8: 0 | U8: 0 | V8: 0 | W8: 0 | X8: 1749 | Y8: 0 | Z8: 0 | AA8: 0 | AB8: 0 | AC8: 0 | AD8: 0 | AE8: 0 | AF8: 0 | AG8: 0 | AH8: 0 | AI8: 0 | AJ8: 0 | AK8: 0 | AL8: 0 | AM8: 0
A9: Closing (£) | B9: 202813.07 | C9: 202124.57 | D9: 201435.19 | E9: 200744.97 | F9: 200053.89 | G9: 199361.95 | H9: 198669.15 | I9: 197275.49 | J9: 195880.1 | K9: 194482.99 | L9: 193084.14 | M9: 191683.56 | N9: 190281.24 | O9: 188877.18 | P9: 187471.37 | Q9: 186063.82 | R9: 184654.52 | S9: 183243.47 | T9: 181830.67 | U9: 180416.11 | V9: 178999.8 | W9: 178281.79 | X9: 179311.84 | Y9: 178764.94 | Z9: 178764.94 | AA9: 178764.94 | AB9: 178764.94 | AC9: 178764.94 | AD9: 178764.94 | AE9: 178764.94 | AF9: 178764.94 | AG9: 178764.94 | AH9: 178764.94 | AI9: 178764.94 | AJ9: 178764.94 | AK9: 178764.94 | AL9: 178764.94 | AM9: 178764.94

Sheet Tax 24-25
A1: Tax calculation — UK 24/25 + Swedish 2024
A3: Parameters (edit these to recalc):
A4: FX rate (SEK per GBP) | B4: 13.50453 | C4: Riksbanken 2024 annual average
A5: UK tax year (label/float) | B5: 24.25 | C5: 24/25
A6: Swedish tax year | B6: 2024 | C6: 2024
A7: UK personal allowance | B7: 12570
A8: UK basic rate | B8: 0.2
A9: UK financing-cost credit rate | B9: 0.2
A10: Swedish standard deduction (SEK) | B10: 40000
A11: Swedish % deduction (of rental income) | B11: 0.2
A12: Swedish capital income tax rate | B12: 0.3
A14: UK tax year 24/25 (6 April to 5 April)
B15: GBP
A16: Rental Income | B16: =SUMIF('76A Ingelow Road'!$C$2:$AY$2,$B$5,'76A Ingelow Road'!$C$6:$AY$6)
A17: Knight Frank Commission (mgmt + letting) | B17: =SUMIF('76A Ingelow Road'!$C$2:$AY$2,$B$5,'76A Ingelow Road'!$C$10:$AY$10)+SUMIF('76A Ingelow Road'!$C$2:$AY$2,$B$5,'76A Ingelow Road'!$C$11:$AY$11)
A18: Net Income before Expenses | B18: =$B$16+$B$17
A19: Repair and Maintenance Expenses | B19: =SUMIF('76A Ingelow Road'!$C$2:$AY$2,$B$5,'76A Ingelow Road'!$C$13:$AY$13)
A20: Taxable Property Profit (SA105 box 38/40) | B20: =$B$18+$B$19
A22: Memo — residential property finance costs (SA105 box 44):
A23: Mortgage interest | B23: =SUMIF('Santander'!$B$3:$AN$3,$C$5,'Santander'!$B$6:$AN$6)
A24: Mortgage product fees | B24: =SUMIF('Santander'!$B$3:$AN$3,$C$5,'Santander'!$B$8:$AN$8)
A25: Total residential finance costs | B25: =$B$23+$B$24
A27: UK tax calculation
A28: Total taxable income (property profit) | B28: =$B$20
A29: Above personal allowance | B29: =MAX(0,$B$20-$B$7)
A30: Basic rate tax (= above PA × basic rate) | B30: =$B$29*$B$8
A31: Less: financing cost credit (finance costs × credit rate) | B31: =-$B$25*$B$9
A32: Net UK Tax | B32: =$B$30+$B$31
A35: Swedish tax year 2024 (1 January to 31 December)
B36: GBP | C36: SEK
A37: Rental Income | B37: =SUMIF('76A Ingelow Road'!$C$1:$AY$1,$B$6,'76A Ingelow Road'!$C$6:$AY$6) | C37: =B37*$B$4
A38: Knight Frank Commission | B38: =SUMIF('76A Ingelow Road'!$C$1:$AY$1,$B$6,'76A Ingelow Road'!$C$10:$AY$10)+SUMIF('76A Ingelow Road'!$C$1:$AY$1,$B$6,'76A Ingelow Road'!$C$11:$AY$11) | C38: =B38*$B$4
A39: Rental income net of commission (basis for schablonavdrag) | B39: =$B$37+$B$38 | C39: =B39*$B$4
A41: Schablonavdrag (replaces actual expense deduction):
A42: Standard SEK 40,000 deduction | B42: =-$B$10/$B$4 | C42: =-$B$10
A43: 20% of rental income (net of commission) | B43: =-$B$39*$B$11 | C43: =B43*$B$4
A44: Box 7.3 — Överskott vid uthyrning av privatbostad | B44: =$B$39+$B$42+$B$43 | C44: =B44*$B$4
A46: Memo — repairs (not deductible under schablonavdrag): | B46: =SUMIF('76A Ingelow Road'!$C$1:$AY$1,$B$6,'76A Ingelow Road'!$C$13:$AY$13)
A48: Box 8.1 — Ränteutgifter (mortgage interest + fees)
A49: Mortgage interest (calendar year) | B49: =SUMIF('Santander'!$B$4:$AN$4,$C$6,'Santander'!$B$6:$AN$6) | C49: =B49*$B$4
...

Sheet Tax 25-26
A1: Tax calculation — UK 25/26 + Swedish 2025
A3: Parameters (edit these to recalc):
A4: FX rate (SEK per GBP) | B4: 12.92163 | C4: Riksbanken 2025 annual average
A5: UK tax year (label/float) | B5: 25.26 | C5: 25/26
A6: Swedish tax year | B6: 2025 | C6: 2025
A7: UK personal allowance | B7: 12570
A8: UK basic rate | B8: 0.2
A9: UK financing-cost credit rate | B9: 0.2
A10: Swedish standard deduction (SEK) | B10: 40000
A11: Swedish % deduction (of rental income) | B11: 0.2
A12: Swedish capital income tax rate | B12: 0.3
A14: UK tax year 25/26 (6 April to 5 April)
B15: GBP
A16: Rental Income | B16: =SUMIF('76A Ingelow Road'!$C$2:$AY$2,$B$5,'76A Ingelow Road'!$C$6:$AY$6)
A17: Knight Frank Commission (mgmt + letting) | B17: =SUMIF('76A Ingelow Road'!$C$2:$AY$2,$B$5,'76A Ingelow Road'!$C$10:$AY$10)+SUMIF('76A Ingelow Road'!$C$2:$AY$2,$B$5,'76A Ingelow Road'!$C$11:$AY$11)
A18: Net Income before Expenses | B18: =$B$16+$B$17
A19: Repair and Maintenance Expenses | B19: =SUMIF('76A Ingelow Road'!$C$2:$AY$2,$B$5,'76A Ingelow Road'!$C$13:$AY$13)
A20: Taxable Property Profit (SA105 box 38/40) | B20: =$B$18+$B$19
A22: Memo — residential property finance costs (SA105 box 44):
A23: Mortgage interest | B23: =SUMIF('Santander'!$B$3:$AN$3,$C$5,'Santander'!$B$6:$AN$6)
A24: Mortgage product fees | B24: =SUMIF('Santander'!$B$3:$AN$3,$C$5,'Santander'!$B$8:$AN$8)
A25: Total residential finance costs | B25: =$B$23+$B$24
A27: UK tax calculation
A28: Total taxable income (property profit) | B28: =$B$20
A29: Above personal allowance | B29: =MAX(0,$B$20-$B$7)
A30: Basic rate tax (= above PA × basic rate) | B30: =$B$29*$B$8
A31: Less: financing cost credit (finance costs × credit rate) | B31: =-$B$25*$B$9
A32: Net UK Tax | B32: =$B$30+$B$31
A35: Swedish tax year 2025 (1 January to 31 December)
B36: GBP | C36: SEK
A37: Rental Income | B37: =SUMIF('76A Ingelow Road'!$C$1:$AY$1,$B$6,'76A Ingelow Road'!$C$6:$AY$6) | C37: =B37*$B$4
A38: Knight Frank Commission | B38: =SUMIF('76A Ingelow Road'!$C$1:$AY$1,$B$6,'76A Ingelow Road'!$C$10:$AY$10)+SUMIF('76A Ingelow Road'!$C$1:$AY$1,$B$6,'76A Ingelow Road'!$C$11:$AY$11) | C38: =B38*$B$4
A39: Rental income net of commission (basis for schablonavdrag) | B39: =$B$37+$B$38 | C39: =B39*$B$4
A41: Schablonavdrag (replaces actual expense deduction):
A42: Standard SEK 40,000 deduction | B42: =-$B$10/$B$4 | C42: =-$B$10
A43: 20% of rental income (net of commission) | B43: =-$B$39*$B$11 | C43: =B43*$B$4
A44: Box 7.3 — Överskott vid uthyrning av privatbostad | B44: =$B$39+$B$42+$B$43 | C44: =B44*$B$4
A46: Memo — repairs (not deductible under schablonavdrag): | B46: =SUMIF('76A Ingelow Road'!$C$1:$AY$1,$B$6,'76A Ingelow Road'!$C$13:$AY$13)
A48: Box 8.1 — Ränteutgifter (mortgage interest + fees)
A49: Mortgage interest (calendar year) | B49: =SUMIF('Santander'!$B$4:$AN$4,$C$6,'Santander'!$B$6:$AN$6) | C49: =B49*$B$4
...

Sheet Capital Gains 2025
A1: Capital Gains 2025 — Vanguard ISA (sold June 2025)
A3: Held in UK ISA → no UK tax. Swedish residency 25 Nov 2021 → cost basis taken at that date.
A4: Swedish capital gains tax: 30% flat on net gain in SEK.
A6: Parameters (edit to recalc):
A7: Cost basis date | B7: 25 Nov 2021 | C7: (Swedish tax-residency start)
A8: Cost basis value (GBP) | B8: 23031.31
A9: Cost basis FX rate (Nov 2021) | B9: 11.84728 | C9: Riksbanken Nov 2021 monthly avg
A10: Sale date | B10: 5 Jun 2025
A11: Sale proceeds (GBP) | B11: 29862.97
A12: Sale FX rate (Jun 2025) | B12: 12.9485 | C12: Riksbanken Jun 2025 monthly avg
A13: Swedish capital tax rate | B13: 0.3
A15: Calculation
B16: GBP | C16: SEK
A17: Cost basis (omkostnadsbelopp) | B17: =$B$8 | C17: =$B$8*$B$9
A18: Sale proceeds (försäljningspris) | B18: =$B$11 | C18: =$B$11*$B$12
A19: Capital gain | B19: =$B$11-$B$8 | C19: =$B$11*$B$12-$B$8*$B$9
A21: Decomposition (memo):
A22: Investment performance in GBP | B22: =$B$11-$B$8
A23: FX uplift on cost basis (Nov21 → Jun25) | C23: =$B$8*($B$12-$B$9)
A24: → Total SEK gain (matches above)
A26: Swedish capital tax (30% of SEK gain) | B26: =$C$19*$B$13/$B$12 | C26: =$C$19*$B$13
A29: Reporting in your Swedish tax return:
A30: • File K4 (bilaga K4) — avsnitt A or C depending on whether marknadsnoterade aktier/fonder
A31: • K4 lists: antal/units, försäljningspris, omkostnadsbelopp, vinst
A32: • Net gain rolls into Box 7.4 (kapitalvinst marknadsnoterade aktier/fonder) on INK1
A33: • Box 7.2 catches general interest/dividends; CGT-specific lines are 7.4/7.5/7.6 depending on type
A35: Assumptions & caveats:
A36: • Cost basis taken at 25 Nov 2021 value (Swedish residency start). This is the simplest approach if
A37: the bulk of the holding pre-dated the move. If significant contributions were made AFTER Nov 2021,
A38: Swedish tax law applies the average-cost method (genomsnittsmetoden) — each contribution's own
A39: cost basis (in SEK at the time) is weighted into the average. Confirm with accountant if you
A40: contributed materially between Nov 2021 and Jun 2025.
A41: • FX rates used are Riksbanken monthly averages for Nov 2021 and Jun 2025.
... A43: • Capital losses elsewhere in the same year can offset this gain (currently none assumed).
